Workbook

Sheet Start Here
A1: The Data Fashion Brief, Outreach Tracker
A2: Brands, media, partners and events in one place. Built 11 October 2026.
A5: Pipeline
A6: Tab | B6: To pitch | C6: Pitched | D6: Followed up | E6: Replied | F6: Booked | G6: Declined | H6: Total
A7: Brands | B7: =COUNTIF(Brands!$F$5:$F$82,"To pitch") -> 38 | C7: =COUNTIF(Brands!$F$5:$F$82,"Pitched") -> 0 | D7: =COUNTIF(Brands!$F$5:$F$82,"Followed up") -> 0 | E7: =COUNTIF(Brands!$F$5:$F$82,"Replied") -> 0 | F7: =COUNTIF(Brands!$F$5:$F$82,"Booked") -> 0 | G7: =COUNTIF(Brands!$F$5:$F$82,"Declined") -> 0 | H7: =COUNTA(Brands!$A$5:$A$82) -> 38
A8: Media | B8: =COUNTIF(Media!$F$5:$F$81,"To pitch") -> 37 | C8: =COUNTIF(Media!$F$5:$F$81,"Pitched") -> 0 | D8: =COUNTIF(Media!$F$5:$F$81,"Followed up") -> 0 | E8: =COUNTIF(Media!$F$5:$F$81,"Replied") -> 0 | F8: =COUNTIF(Media!$F$5:$F$81,"Booked") -> 0 | G8: =COUNTIF(Media!$F$5:$F$81,"Declined") -> 0 | H8: =COUNTA(Media!$A$5:$A$81) -> 37
A9: Partners & Speaking | B9: =COUNTIF('Partners & Speaking'!$F$5:$F$63,"To pitch") -> 19 | C9: =COUNTIF('Partners & Speaking'!$F$5:$F$63,"Pitched") -> 0 | D9: =COUNTIF('Partners & Speaking'!$F$5:$F$63,"Followed up") -> 0 | E9: =COUNTIF('Partners & Speaking'!$F$5:$F$63,"Replied") -> 0 | F9: =COUNTIF('Partners & Speaking'!$F$5:$F$63,"Booked") -> 0 | G9: =COUNTIF('Partners & Speaking'!$F$5:$F$63,"Declined") -> 0 | H9: =COUNTA('Partners & Speaking'!$A$5:$A$63) -> 19
A10: All contacts | B10: =SUM(B7:B9) -> 94 | C10: =SUM(C7:C9) -> 0 | D10: =SUM(D7:D9) -> 0 | E10: =SUM(E7:E9) -> 0 | F10: =SUM(F7:F9) -> 0 | G10: =SUM(G7:G9) -> 0 | H10: =SUM(H7:H9) -> 94
A12: Events
A13: Status | B13: Want to go | C13: Applied | D13: Invited | E13: Going | F13: Went | G13: Skip
A14: Events | B14: =COUNTIF(Events!$G$5:$G$74,"Want to go") -> 40 | C14: =COUNTIF(Events!$G$5:$G$74,"Applied") -> 0 | D14: =COUNTIF(Events!$G$5:$G$74,"Invited") -> 0 | E14: =COUNTIF(Events!$G$5:$G$74,"Going") -> 0 | F14: =COUNTIF(Events!$G$5:$G$74,"Went") -> 0 | G14: =COUNTIF(Events!$G$5:$G$74,"Skip") -> 0
A15: Overdue follow-ups | B15: =SUMPRODUCT((Brands!$H$5:$H$82<>"")*(Brands!$H$5:$H$82<=TODAY())*(Brands!$F$5:$F$82="Pitched"))+SUMPRODUCT((Brands!$H$5:$H$82<>"")*(Brands!$H$5:$H$82<=TODAY())*(Brands!$F$5:$F$82="Followed up"))+SUMPRODUCT((Media!$H$5:$H$81<>"")*(Media!$H$5:$H$81<=TODAY())*(Media!$F$5:$F$81="Pitched"))+SUMPRODUCT((Media!$H$5:$H$81<>"")*(Media!$H$5:$H$81<=TODAY())*(Media!$F$5:$F$81="Followed up"))+SUMPRODUCT(('Partners & Speaking'!$H$5:$H$63<>"")*('Partners & Speaking'!$H$5:$H$63<=TODAY())*('Partners & Speaking'!$F$5:$F$63="Pitched"))+SUMPRODUCT(('Partners & Speaking'!$H$5:$H$63<>"")*('Partners & Speaking'!$H$5:$H$63<=TODAY())*('Partners & Speaking'!$F$5:$F$63="Followed up")) -> 0 | C15: Pitched or followed up 7+ days ago with no reply yet
A17: How to use it
A18: • Yellow cells are the ones you fill in: Status (pick from the dropdown) and Last contact (the date you sent the pitch or follow-up).
A19: • Follow up by fills itself in 7 days after Last contact, and turns red once it's due and you still haven't had a reply.
A20: • Rows change colour with status: amber once pitched, green once they reply or book, grey if declined.
A21: • Every contact was published by the organisation itself (press pages, staff pages, official releases). None were guessed. Click Where contact is published to check it before you send, because these were found through search results rather than by opening each page.
A22: • Flags marks Farfetch competitors and ex-employers (check your contract before any paid deal) and contacts or routes that are unverified.
A23: • Add new rows at the bottom of any tab. Dropdowns and formulas are already set up for about 40 more rows per tab.
A24: • Pitch drafts live in drafts/outreach-pitches-draft.md in the repo.
A26: Start this week
A27: • Request a BoF VOICES invite (form open now, 1 to 4 December).
A28: • Sign up to ShopMy and LTK as a creator.
A29: • Pitch three High-priority brands, each with one real data point about that brand.
... A31: • Ask the British Fashion Council press office about media accreditation for The Fashion Awards (30 November).

Sheet Brands
A1: Brands
A2: Contemporary and luxury brands plus retailers and affiliate platforms, US first, sorted by priority
A4: Name | B4: Type | C4: Segment | D4: Market | E4: Priority | F4: Status | G4: Last contact | H4: Follow up by | I4: Contact | J4: Where contact is published | K4: Why it fits | L4: Pitch angle | M4: How to reach | N4: Source link | O4: Flags | P4: Notes
A5: Aritzia | B5: Brand | C5: Contemporary | D5: US + Canada | E5: High | F5: To pitch | H5: =IF(G5="","",G5+7) | I5: Press and influencer addresses on their media room page (masked in search, open the page) | J5: https://www.aritzia.com/us/en/aritzia/corporate-hub/corporate-media-room | K5: US net revenue up 44% in fiscal 2026 per the CEO, a made-for-data US growth story | L5: Why US shoppers went for Aritzia, told through search and product data | M5: No public route found, Instagram DM or LinkedIn PR lead | N5: https://www.marketbeat.com/instant-alerts/aritzia-shareholders-back-board-as-ceo-touts-35-revenue-growth-us-expansion-2026-07-13/ | O5: Route unverified, check before sending
A6: Coach | B6: Brand | C6: Luxury | D6: US | E6: High | F6: To pitch | H6: =IF(G6="","",G6+7) | I6: media@tapestry.com (Tapestry press office) | J6: https://www.tapestry.com/contact/ | K6: Strongest data story on the list: Coach revenue up 24% in fiscal 2026, about 35% of Tapestry's new customers were Gen Z, and No. 9 on the Lyst Index Q2 2026 | L6: A Gen Z and the handbag data piece, or a Trend Autopsy with Coach as the picks | M6: In-house influencer and creator marketing team in New York (job ads), plus a London PR role covering Coach and Kate Spade, no affiliate page found | N6: https://pulse2.com/tapestry-11-million-new-customers-join-in-fy26-as-gen-z-represents-35-of-acquisitions/ | O6: Route unverified, check before sending | P6: Figures from secondary sources, check Tapestry's own release before quoting. Corporate comms. A recent release also names a Sr Director Communications, and the London PR role covers Coach UK
A7: ME+EM | B7: Brand | C7: Contemporary | D7: UK + US | E7: High | F7: To pitch | H7: =IF(G7="","",G7+7) | I7: press@meandem.com | J7: https://www.meandem.com/us/contact | K7: London brand with US sales up 61% to £47m in the year to January 2025, stores in New York, Dallas, LA and Greenwich | L7: A London to US data story, which is exactly your audience split | M7: No public route found, Instagram DM or LinkedIn PR lead | N7: https://fashionunited.com/news/business/me-em-welcomes-strong-growth-as-us-market-drives-performance/2025103168975 | O7: Route unverified, check before sending | P7: Latest figures are from 2025
A8: Ralph Lauren | B8: Brand | C8: Luxury | D8: US | E8: High | F8: To pitch | H8: =IF(G8="","",G8+7) | I8: RL-Press@ralphlauren.com | J8: https://corporate.ralphlauren.com/contact | K8: Fiscal 2026 revenue up 15% to over $8bn, 6.5m new direct customers, a stated push for younger shoppers, and No. 7 on Lyst Q2 2026 | L8: The younger customer story, and Ralph Lauren was one of the houses where denim showed up most in your NYFW SS27 data | M8: No public route found, LinkedIn PR lead | N8: https://www.sec.gov/Archives/edgar/data/0001037038/000162828026037053/rl-20260328xex991xpressrel.htm
A9: Reformation | B9: Brand | C9: Contemporary | D9: US | E9: High | F9: To pitch | H9: =IF(G9="","",G9+7) | I9: press@thereformation.com | J9: https://help.thereformation.com/en_us/contact/contact-us-HJbQdfdHj | K9: Newly public in 2026, Q2 revenue up 24% to $155m, its 21st straight quarter of double-digit growth | L9: Data read of a brand that keeps growing, plus shoppable picks | M9: Affiliate programme exists, third parties disagree on terms | N9: https://affilimate.com/programs/reformation-affiliate-program/ | O9: Route unverified, check before sending
A10: Tibi | B10: Brand | C10: Contemporary | D10: US | E10: High | F10: To pitch | H10: =IF(G10="","",G10+7) | I10: press@tibi.com | J10: https://tibi.com/pages/customer-care | K10: Founder Amy Smilovic writes her own Substack, so a newsletter-native collab is plausible | L10: Substack collab or cross-post on how to actually build a wardrobe from trends | M10: Substack DM to the founder, otherwise Instagram DM | N10: https://www.disneyrollergirl.net/fashion-founder-substacks-influencers/ | O10: Route unverified, check before sending | P10: Check her Substack is still active in 2026. Covers PR, events and samples
A11: Toteme | B11: Brand | C11: Luxury | D11: EU + US | E11: High | F11: To pitch | H11: =IF(G11="","",G11+7) | I11: press@toteme.com | J11: https://toteme-studio.com/pages/contact | K11: Expanding in the US with a Bal Harbour store (July 2026) and its first Texas store in Dallas | L11: Quiet dressing, measured: what the data says about the minimalist wardrobe | M11: No public route found, Instagram DM | N11: https://www.papercitymag.com/fashion/knox-street-announces-new-retailers-2026/ | O11: Route unverified, check before sending
A12: Ulla Johnson | B12: Brand | C12: Contemporary | D12: US + UK | E12: High | F12: To pitch | H12: =IF(G12="","",G12+7) | I12: press@ullajohnson.com | J12: https://ullajohnson.com/pages/contact | K12: Opened its first store outside the US on Sloane Street, London, in September 2026 | L12: US brand landing in London, a clean fit for a US and UK audience | M12: No public route found, Instagram DM or LinkedIn PR lead | N12: https://fashionunited.uk/news/retail/ulla-johnson-opens-first-standalone-store-outside-us-in-london/2026090390118 | O12: Route unverified, check before sending
A13: Veronica Beard | B13: Brand | C13: Contemporary | D13: US | E13: High | F13: To pitch | H13: =IF(G13="","",G13+7) | I13: press@veronicabeard.com | J13: https://veronicabeard.com/pages/press | K13: Runs an in-house affiliate programme with a dedicated partnerships manager, the most realistic quick yes | L13: Workwear trend piece with Veronica Beard as the picks | M13: Affiliate programme (FlexOffers listing), in-house partnerships team | N13: https://veronicabeard.com/blogs/career/affiliate-digital-partnerships-manager
A14: Cult Gaia | B14: Brand | C14: Contemporary | D14: US | E14: Medium | F14: To pitch | H14: =IF(G14="","",G14+7) | I14: pr@cultgaia.com | J14: https://cultgaia.com/pages/work-with-us | K14: Showed its first NYFW runway for Fall/Winter 2026 | L14: Runway debut decoded with your tagging | M14: No public route found, Instagram DM | N14: https://www.nssmag.com/en/fashion/44248/nyfw-fw26-debuts-proenza-schouler-calvin-klein-cult-gaia-n4xt | O14: Route unverified, check before sending | P14: Replies in 3 to 5 business days
A15: Dôen | B15: Brand | C15: Contemporary | D15: US | E15: Medium | F15: To pitch | H15: =IF(G15="","",G15+7) | I15: press@shopdoen.com | J15: https://www.shopdoen.com/pages/contact | K15: LA brand opening its first Texas store in 2026 | L15: Romantic prairie dressing, trend or not? | M15: No public route found, Instagram DM | N15: https://www.papercitymag.com/fashion/knox-street-announces-new-retailers-2026/ | O15: Route unverified, check before sending
A16: Frame / Agolde | B16: Brand | C16: Contemporary | D16: US | E16: Medium | F16: To pitch | H16: =IF(G16="","",G16+7) | I16: Agolde press: AJoines@citizensofhumanity.com (Frame has none published) | J16: https://agolde.com/pages/sales-press | K16: Premium denim, and denim was in 38% of NYFW SS27 catwalks in your own data | L16: Denim data piece with them as the picks | M16: Frame affiliate on Daisycon (status unclear), Agolde no public route | N16: https://www.daisycon.com/sv/kampanj/18386-frame-int/ | O16: Route unverified, check before sending
A17: Jenni Kayne | B17: Brand | C17: Contemporary | D17: US | E17: Medium | F17: To pitch | H17: =IF(G17="","",G17+7) | K17: Glossy covered how its NYFW event won it valuable cross-category shoppers | L17: Event invite plus a data piece on the California minimalist look | M17: Hosts press and influencers at its NYFW events, Instagram DM | N17: https://www.glossy.co/fashion/how-jenni-kayne-used-its-nyfw-show-to-acquire-valuable-cross-category-shoppers/ | O17: Route unverified, check before sending
A18: Khaite | B18: Brand | C18: Luxury | D18: US | E18: Medium | F18: To pitch | H18: =IF(G18="","",G18+7) | I18: press@khaite.com | J18: https://khaite.com/pages/contact-us | K18: A Lyst favourite with stores in SoHo and Dallas, and strong on named trends in your NYFW SS27 data | L18: Data portrait of a house that leads the season's named trends | M18: No public route found, Instagram DM or LinkedIn PR lead | N18: https://www.papercitymag.com/fashion/khaite-dallas-new-store-shopping-clothing-quiet-luxury/ | O18: Route unverified, check before sending | P18: Source snapshot is old, check it still works
A19: Miu Miu (editorial subject) | B19: Brand | C19: Luxury | D19: Global | E19: Medium | F19: To pitch | H19: =IF(G19="","",G19+7) | K19: No. 2 on Lyst Q2 2026 with searches up 30%, but H1 2026 retail sales grew only about 3% | L19: Perfect Stop Calling Everything a Trend piece: buzz versus sales | M19: Not a realistic partner yet, write about it instead | N19: https://fashionunited.com/news/business/prada-group-closes-h1-with-a-16-percent-increase-in-net-revenue/2026073073824
A20: Polène | B20: Brand | C20: Contemporary | D20: EU + US | E20: Medium | F20: To pitch | H20: =IF(G20="","",G20+7) | I20: contact@polene-paris.com (also for partnership applications) | J20: https://support.polene-paris.com/hc/en-us/articles/360010129820 | K20: Opened in New York and says sales double every year, figures not disclosed | L20: The it-bag that isn't a logo bag, search data angle | M20: No public route found, Instagram DM | N20: https://www.glossy.co/fashion/french-brands-are-expanding-their-retail-presence-to-the-u-s/ | O20: Route unverified, check before sending
A21: Proenza Schouler | B21: Brand | C21: Luxury | D21: US | E21: Medium | F21: To pitch | H21: =IF(G21="","",G21+7) | I21: press@proenzaschouler.com | J21: https://www.proenzaschouler.com/pages/contact-us | K21: New creative director Rachel Scott debuted with Fall/Winter 2026 after the founders left for Loewe | L21: Before and after data piece on a creative director change | M21: No public route found, LinkedIn PR lead | N21: https://www.theindustry.fashion/proenza-schouler-names-rachel-scott-as-creative-director/ | O21: Route unverified, check before sending
A22: Rixo | B22: Brand | C22: Contemporary | D22: UK + US | E22: Medium | F22: To pitch | H22: =IF(G22="","",G22+7) | I22: press@rixo.co.uk | J22: https://www.rixo.co.uk/contact/ | K22: Says its SoHo store drove a 43% rise in US direct sales after the 2024 pop-up went permanent | L22: London print brand in New York, through data | M22: No public route found, Instagram DM | N22: https://us.fashionnetwork.com/news/Rixo-makes-nyc-pop-up-a-permanent-store,1659332.html | O22: Route unverified, check before sending | P22: Data is from 2024. Source snapshot is old, check it still works
A23: Staud | B23: Brand | C23: Contemporary | D23: US | E23: Medium | F23: To pitch | H23: =IF(G23="","",G23+7) | I23: press@staud.clothing | J23: https://staud.clothing/pages/contact-us | K23: Opening its first Texas store in 2026, and its signature bags are perfect Trend Autopsy material | L23: Is the Staud bag still a trend? Search data says... | M23: Affiliate programmes listed as closed, Instagram DM | N23: https://www.papercitymag.com/fashion/knox-street-announces-new-retailers-2026/ | O23: Route unverified, check before sending
A24: Sézane | B24: Brand | C24: Contemporary | D24: EU + US | E24: Medium | F24: To pitch | H24: =IF(G24="","",G24+7) | I24: Contact form, topic Press and partnerships | J24: https://www.sezane.com/us-en/contact | K24: Keeps opening US stores, with Washington DC opening in April 2026 | L24: French brand winning American shoppers, told through data | M24: Awin UK merchant profile, otherwise Instagram DM | N24: https://fashionunited.com/news/retail/sezane-to-open-new-us-store-in-washington-in-april/2026020470406
A25: Tory Burch | B25: Brand | C25: Luxury | D25: US | E25: Medium | F25: To pitch | H25: =IF(G25="","",G25+7) | I25: press@toryburch.com, partnerships: marketing@toryburch.com | J25: https://www.toryburch.com/on/demandware.store/Sites-ToryBurch_EU-Site/en/CustomerService-ContactUs | K25: US-heavy accessible luxury, no 2026 data found | L25: Affiliate for picks | M25: Affiliate listings (US status unclear, UK about 2%) | N25: https://www.flexoffers.com/affiliate-programs/tory-burch-affiliate-program/ | O25: Route unverified, check before sending
A26: Vince | B26: Brand | C26: Contemporary | D26: US | E26: Medium | F26: To pitch | H26: =IF(G26="","",G26+7) | K26: Q2 2026 net sales up 12% to $82m, guidance raised, and it bought OVO to move into streetwear | L26: Data read of a quiet brand turning around | M26: No public route found, LinkedIn PR lead | N26: https://secure.businesswire.com/news/home/20260910767018/en/Vince-Holding-Corp.-Reports-Second-Quarter-2026-Results | O26: Route unverified, check before sending
A27: Gabriela Hearst / Altuzarra | B27: Brand | C27: Luxury | D27: US | E27: Low | F27: To pitch | H27: =IF(G27="","",G27+7) | K27: New York luxury, no strong 2026 business hook found | L27: Editorial subject first | M27: No public route found, LinkedIn PR lead | N27: https://ww.fashionnetwork.com/tags-gabriela-hearst | O27: Route unverified, check before sending
A28: Jacquemus | B28: Brand | C28: Luxury | D28: EU + US | E28: Low | F28: To pitch | H28: =IF(G28="","",G28+7) | K28: The US is reportedly its biggest market, with stores in LA and SoHo | L28: Data read on the novelty bag | M28: No public route found, Instagram DM | N28: https://fashionunited.com/news/retail/jacquemus-opens-in-los-angeles-on-melrose-avenue/2025042465643 | O28: Route unverified, check before sending
A29: Sandy Liang / Ganni | B29: Brand | C29: Contemporary | D29: US / EU + US | E29: Low | F29: To pitch | H29: =IF(G29="","",G29+7) | I29: Ganni London PR (DH-PR): ganni@dh-pr.com, HQ: press@ganni.com | J29: https://www.ganni.com/us/press-showrooms.html | K29: Cult downtown and Scandi labels, no 2026 business data found | L29: Trend Autopsy picks | M29: No public route found, Instagram DM | N29: https://www.instagram.com | O29: Route unverified, check before sending
A30: The Row (editorial subject) | B30: Brand | C30: Luxury | D30: US | E30: Low | F30: To pitch | H30: =IF(G30="","",G30+7) | K30: Avoids influencers, advertising and gifting, and banned phones from its shows | L30: Write about it, don't pitch it | M30: None, the brand avoids creators | N30: https://graziamagazine.com/us/articles/the-row-paris-fashion-week-no-social-media/ | O30: Route unverified, check before sending
A31: Liberty London | B31: Retail / affiliate | E31: High | F31: To pitch | H31: =IF(G31="","",G31+7) | K31: London heritage, curated, the right register for DFB readers | L31: Affiliate for Exhibit A picks | M31: Official affiliate page, UK runs through Rakuten | N31: https://libertylondon.com/uk/information/the-liberty-london-affiliate-program.html
A32: LTK | B32: Retail / affiliate | C32: Retailer | D32: US + UK | E32: High | F32: To pitch | H32: =IF(G32="","",G32+7) | K32: Creator shoppable-link platform with about 3,700 brands, and its Quick Collabs (March 2026) pays flat fees within 48 to 72 hours | L32: Join as a creator for Trend Autopsy picks | M32: Sign up as a creator, no UK eligibility page verified | N32: https://secure.businesswire.com/news/home/20260318912197/en/LTK-Launches-Quick-Collabs-A-Faster-Way-for-Brands-and-Creators-to-Work-Together
A33: Nordstrom | B33: Retail / affiliate | C33: Retailer | D33: US | E33: High | F33: To pitch | H33: =IF(G33="","",G33+7) | I33: influencers@nordstrom.com (partnerships), NordstromPR@Nordstrom.com (press) | J33: https://www.nordstrom.com/browse/about/nordstrom-media-network | K33: Big US department store, its own page says creator affiliates go through Rakuten, LTK and ShopStyle | L33: Affiliate for picks across contemporary brands | M33: Rakuten, LTK or ShopStyle | N33: https://nordstrom.gcs-web.com/work-us-0 | O33: Some luxury overlap with Farfetch
A34: Shopbop | B34: Retail / affiliate | C34: Retailer | D34: US | E34: High | F34: To pitch | H34: =IF(G34="","",G34+7) | K34: Open influencer and affiliate programme that moves top performers up to a managed tier, and it covers many of the brands above at once | L34: Affiliate for every Trend Autopsy | M34: Apply to the influencer programme, links run through Amazon Associates | N34: https://getlasso.co/affiliate/shopbop/ | O34: Partial overlap with Farfetch on contemporary brands; Route unverified, check before sending
A35: ShopMy | B35: Retail / affiliate | C35: Retailer | D35: US + UK | E35: High | F35: To pitch | H35: =IF(G35="","",G35+7) | K35: Creator platform positioned for premium and luxury brands, raised $70m at a $1.5bn valuation in 2025 | L35: Join as a creator, it's where premium brands look for partners | M35: Apply as a creator | N35: https://pulse2.com/shopmy-70-million-at-1-5-billion-valuation-raised-for-expanding-curated-commerce-infrastructure-for-premium-brands
A36: Revolve | B36: Retail / affiliate | C36: Retailer | D36: US | E36: Medium | F36: To pitch | H36: =IF(G36="","",G36+7) | I36: revolveus@karlaotto.com (Karla Otto, Revolve's PR) | J36: https://investors.revolve.com/news/news-details/2026/Revolve-Group-Announces-Second-Quarter-2026-Financial-Results/default.aspx | K36: US contemporary retailer with a Brand Ambassador programme paying commission | L36: Affiliate for picks | M36: Brand Ambassador programme | N36: https://investors.revolve.com/files/doc_news/REVOLVE-Launches-Brand-Ambassador-Program-Leveraging-in-House-Proprietary-Technology-2021.pdf
A37: Whatnot | B37: Retail / affiliate | E37: Medium | F37: To pitch | H37: =IF(G37="","",G37+7) | K37: You went to their LFW event, UK creator programme launched May 2026 | L37: Live-shopping trend explainer or creator programme | M37: Check the creator terms on Whatnot directly, warm contact from the event | N37: https://www.whatnot.com | O37: Route unverified, check before sending
A38: FWRD | B38: Retail / affiliate | C38: Retailer | D38: US | E38: Low | F38: To pitch | H38: =IF(G38="","",G38+7) | K38: Revolve's luxury site with an ambassador and affiliate programme | L38: Affiliate | M38: Official affiliate page | N38: https://www.fwrd.com/fw/Affiliate.jsp | O38: Competitor: luxury e-commerce | P38: Probably skip while at Farfetch
A39: Mytheresa | B39: Retail / affiliate | E39: Low | F39: To pitch | H39: =IF(G39="","",G39+7) | K39: Luxury affiliate with an official page | L39: Affiliate | M39: Official affiliate page | N39: https://www.mytheresa.com/me/en/affiliates | O39: Competitor: luxury marketplace | P39: Probably skip while at Farfetch
A40: Net-a-Porter / Mr Porter | B40: Retail / affiliate | E40: Low | F40: To pitch | H40: =IF(G40="","",G40+7) | K40: Luxury affiliate | L40: Affiliate | M40: Affiliate networks per aggregators | N40: https://www.net-a-porter.com | O40: Competitor and ex-employer (YNAP); Route unverified, check before sending | P40: Probably skip while at Farfetch
A41: Saks / Neiman Marcus / Bergdorf | B41: Retail / affiliate | C41: Retailer | D41: US | E41: Low | F41: To pitch | H41: =IF(G41="","",G41+7) | K41: Came out of Chapter 11 in June 2026 as Exemplar Luxury Group, about 100 stores closed | L41: Editorial subject rather than partner right now | M41: No route verified | N41: https://news.bloomberglaw.com/bankruptcy-law/saks-global-emerges-from-bankruptcy-as-exemplar-luxury-group | O41: Competitor: Saks online; Route unverified, check before sending
...

Sheet Media
A1: Media
A2: Magazines, trade titles, newsletters, podcasts and expert-source platforms for the DFB for [Outlet] pitch
A4: Name | B4: Type | C4: Segment | D4: Market | E4: Priority | F4: Status | G4: Last contact | H4: Follow up by | I4: Contact | J4: Where contact is published | K4: Why it fits | L4: Pitch angle | M4: How to reach | N4: Source link | O4: Flags | P4: Notes
A5: Business of Fashion | B5: Media | E5: High | F5: To pitch | H5: =IF(G5="","",G5+7) | I5: contributors@businessoffashion.com, subject Op-Ed, 700 to 1,000 words, exclusive | J5: https://www.businessoffashion.com/contact-us/ | K5: The B2B reference for fashion business analysis and data | L5: Runway tagging against Google search, which SS27 trends shoppers actually searched for | M5: Contact page asks for targeted, concise pitches and warns they can't reply to all | N5: https://www.businessoffashion.com/contact | P5: No op-ed process found, keep the pitch short and data-first
A6: Drapers | B6: Media | E6: High | F6: To pitch | H6: =IF(G6="","",G6+7) | I6: Features: Emma.finamore@emap.com, news tips: chloe.mills@emap.com, editor: jill.geoghegan@emap.com | J6: https://www.drapersonline.com/contact-us | K6: UK fashion retail trade, your London plus Zara, YNAP background is exactly their reader | L6: Which of this season's trends are worth buying into, according to the data | M6: Contact page lists a fashion editor and a general drapers@emap.com address, but sources disagree on who the current editor is | N6: https://www.drapersonline.com/contact-us | O6: Route unverified, check before sending | P6: Check the named editor on the live page before sending
A7: Grazia UK | B7: Media | E7: High | F7: To pitch | H7: =IF(G7="","",G7+7) | I7: feedback@graziamagazine.co.uk (editorial enquiries) | J7: https://graziadaily.co.uk/contact/ | K7: Features desk commissions zeitgeisty trend pieces, and has a new editor this month | L7: Trend or not? A data verdict on one viral item | M7: No pitch address found, new editor Frances Hedges from October 2026 per Bauer's appointment notice | N7: https://www.inpublishing.co.uk | O7: Route unverified, check before sending | P7: New editor means new commissioning, good timing, LinkedIn route. Fashion team on the About page includes the Style Director and Senior Fashion Features Editor, no emails published
A8: TheIndustry.fashion | B8: Media | E8: High | F8: To pitch | H8: =IF(G8="","",G8+7) | I8: press@theindustry.fashion, team page lists the editor-in-chief and news editor | J8: https://www.theindustry.fashion/the-team/ | K8: UK trade title with its own data products, takes guest content from people working in the industry | L8: A seasonal guest column on runway versus search data | M8: Guest content accepted from industry professionals, policy found on sister site TheIndustry.beauty | N8: https://theindustry.beauty/editorial-policy | O8: Route unverified, check before sending | P8: Co-founder Lauretta Roberts is ex-Drapers and ex-WGSN
A9: Vogue Business | B9: Media | E9: High | F9: To pitch | H9: =IF(G9="","",G9+7) | I9: No pitch inbox published, go via named editors on LinkedIn | J9: https://www.voguebusiness.com | K9: Quotes data analysts and has featured trend-data newsletters before | L9: Expert source on how far runway colour indexes match search demand | M9: Only general addresses found (contact@ and feedback@voguebusiness.com), and from a staging copy of their contact page | N9: https://www.voguebusiness.com | O9: Route unverified, check before sending | P9: Better route is probably LinkedIn to a named editor
A10: Who What Wear UK | B10: Media | E10: High | F10: To pitch | H10: =IF(G10="","",G10+7) | I10: pr@futurenet.com (Future plc, interviews and press requests) | J10: https://www.whowhatwear.com/about-who-what-wear | K10: Already runs round-ups surveying Substack writers on trends | L10: Ask to be included in their next Substack trend survey | M10: No pitch route found, DM the writer of the Substack round-up | N10: https://www.whowhatwear.com/fashion/substack-fall-2026-fashion-trends | O10: Route unverified, check before sending | P10: Easy warm entry, they're already looking for people like you
A11: Dazed | B11: Media | E11: Medium | F11: To pitch | H11: =IF(G11="","",G11+7) | I11: pr@dazedmedia.com, partnerships@dazedmedia.com | J11: https://www.dazeddigital.com/contact | K11: Has an official pitching guide and a culture-first audience | L11: Why TikTok micro-trends don't show up in search data | M11: Subject line PITCH, 300 words max, addressed to the relevant section editor | N11: https://www.dazeddigital.com | P11: For editorial pitches, find the section editor's name on the contact page. Put PITCH in the subject and keep it under 300 words
A12: Glossy | B12: Media | E12: Medium | F12: To pitch | H12: =IF(G12="","",G12+7) | I12: Zofia Zwieglinska, fashion reporter: zofia@glossy.co, Danny Parisi, senior fashion reporter: danny@glossy.co | J12: https://www.glossy.co/masthead/ | K12: Fashion business title that values data-driven analysis, its podcast also takes trend guests | L12: Data piece on trend lifecycles | M12: Masthead on the About page, no pitch inbox found | N12: https://www.glossy.co/about-us | P12: Both addresses are printed in their own articles, Zofia's Luxury Briefing asks for tips
A13: i-D | B13: Media | E13: Medium | F13: To pitch | H13: =IF(G13="","",G13+7) | I13: pitches@i-d.co (subject PITCH: headline) | J13: https://i-d.co/article/how-to-pitch-to-i-d/ | K13: Explicitly asks for pitches backed by pre-reported stats | L13: Internet trend versus runway reality, backed by search data | M13: pitches@i-d.co with subject PITCH, three to four paragraphs | N13: https://i-d.co/article/how-to-pitch-to-i-d/ | O13: Route unverified, check before sending | P13: The guide is about six years old. Address only confirmed on a third-party repost
A14: London Standard | B14: Media | E14: Medium | F14: To pitch | H14: =IF(G14="","",G14+7) | K14: London daily, natural home for a London Fashion Week data read-out | L14: LFW data read-out | M14: Fashion editor listed on Muck Rack (undated), no email found | N14: https://muckrack.com/joe-bromley | O14: Route unverified, check before sending | P14: Confirm the editor is still in post
A15: Modaes | B15: Media | E15: Medium | F15: To pitch | H15: =IF(G15="","",G15+7) | K15: Spain's main fashion business outlet, fits your Inditex background | L15: Spanish-language tribuna on data in trend forecasting | M15: Newsroom page with phone number, opinion pieces seem to be by invitation | N15: https://www.modaes.com/redaccion | P15: Spanish route, LinkedIn to an editor may work better than the phone
A16: S Moda (El País) | B16: Media | E16: Medium | F16: To pitch | H16: =IF(G16="","",G16+7) | K16: Spain's leading fashion supplement | L16: Zara-trained analyst on which trends actually hold up | M16: No public route found | N16: https://smoda.elpais.com | O16: Route unverified, check before sending | P16: LinkedIn to a fashion editor
A17: Stylist | B17: Media | E17: Medium | F17: To pitch | H17: =IF(G17="","",G17+7) | K17: Official freelance guide, reader-friendly trend coverage | L17: The trends you'll actually still wear next year, data-backed | M17: digital.commissions@stylist.co.uk for web pitches | N17: https://www.stylist.co.uk | O17: Route unverified, check before sending | P17: Guide is about four years old
A18: WWD | B18: Media | E18: Medium | F18: To pitch | H18: =IF(G18="","",G18+7) | I18: press@wwd.com, plus a tip form | J18: https://wwd.com/news-tip/ | K18: Trade daily that quotes experts in runway season round-ups | L18: Data comment for their runway-season round-ups | M18: Editorial email button on the contact page, press@wwd.com on the About page | N18: https://wwd.com/contact-us/
A19: Fashionista | B19: Media | E19: Low | F19: To pitch | H19: =IF(G19="","",G19+7) | I19: tips@fashionista.com (put pitch in the subject) | J19: https://fashionista.com/page/contact | K19: Business-leaning consumer title that pays freelancers | L19: Reported piece on how trend forecasting uses search data | M19: Only old freelance-listing addresses found, nothing on the site itself | N19: https://fashionista.com | O19: Route unverified, check before sending | P19: Confirm the current editor before pitching
A20: Hypebeast | B20: Media | E20: Low | F20: To pitch | H20: =IF(G20="","",G20+7) | K20: Streetwear and culture data stories | L20: Menswear runway versus search data | M20: editorial@hypebeast.com, labelled for corrections and inquiries rather than tips | N20: https://hypebeast.com | O20: Route unverified, check before sending
A21: Refinery29 UK | B21: Media | E21: Low | F21: To pitch | H21: =IF(G21="","",G21+7) | K21: Fashion section uses freelancers | L21: Data take on a viral aesthetic | M21: Only old editor addresses found (2022) | N21: https://www.refinery29.com/en-gb | O21: Route unverified, check before sending
A22: Telva / Harper's Bazaar ES / ELLE ES | B22: Media | E22: Low | F22: To pitch | H22: =IF(G22="","",G22+7) | K22: Spanish glossies | L22: Spanish-language trend verdicts | M22: No public editorial email found for any of them | N22: https://www.telva.com | O22: Route unverified, check before sending | P22: LinkedIn
A23: The Guardian fashion | B23: Media | E23: Low | F23: To pitch | H23: =IF(G23="","",G23+7) | K23: National fashion desk with a broad reach | L23: Data column on what's actually trending this season | M23: No fashion desk email found, only confidential-tips channels (the wrong route) | N23: https://www.theguardian.com/fashion | O23: Route unverified, check before sending | P23: LinkedIn or X/Bluesky DM
A24: Vogue España | B24: Media | E24: Low | F24: To pitch | H24: =IF(G24="","",G24+7) | K24: Prestige Spanish title | L24: Which trends hold up, data verdict in Spanish | M24: No public route found | N24: https://www.vogue.es | O24: Route unverified, check before sending | P24: LinkedIn
A25: POST-TASTE (Trina Maraczi) | B25: Newsletter | E25: High | F25: To pitch | H25: =IF(G25="","",G25+7) | K25: Writes trend reports using runway and resale data | L25: Cross-post or recommendation swap | M25: Substack DM | N25: https://posttastebytrina.substack.com
A26: Style Analytics (Molly Rooyakkers) | B26: Newsletter | E26: High | F26: To pitch | H26: =IF(G26="","",G26+7) | K26: Your closest peer, data-driven trend research, has been featured in Vogue Business | L26: Joint post comparing runway tags with search data, or a recommendation swap | M26: Substack DM or recommendation swap | N26: https://styleanalytics.substack.com/about
A27: Back Row (Amy Odell) | B27: Newsletter | E27: Medium | F27: To pitch | H27: =IF(G27="","",G27+7) | K27: Large, business-leaning fashion newsletter, now on beehiiv at backrow.net | L27: Offer data for one of her Q&As | M27: No guest route found | N27: https://backrow.net | O27: Route unverified, check before sending | P27: Moved off Substack
A28: Big Style, CNN (Rachel Tashjian) | B28: Newsletter | E28: Medium | F28: To pitch | H28: =IF(G28="","",G28+7) | K28: Formerly Opulent Tips, now CNN's fashion newsletter | L28: Source pitch with one strong data finding | M28: No route found | N28: https://cnnpressroom.blogs.cnn.com | O28: Route unverified, check before sending
A29: Line Sheet, Puck (Lauren Sherman) | B29: Newsletter | E29: Medium | F29: To pitch | H29: =IF(G29="","",G29+7) | K29: Fashion business intel newsletter | L29: Exclusive data nugget as a tip | M29: No route found | N29: https://puck.news/line-sheet | O29: Route unverified, check before sending
A30: Shop Rat (Emilia Petrarca) | B30: Newsletter | E30: Medium | F30: To pitch | H30: =IF(G30="","",G30+7) | K30: Has run Substack fashion week panels | L30: Data versus what people actually wear on the street, or a panel spot | M30: Substack DM | N30: https://emiliapetrarca.substack.com/about
A31: Thank You For Your Order (Gijs Veening) | B31: Newsletter | E31: Low | F31: To pitch | H31: =IF(G31="","",G31+7) | K31: Small newsletter featured in FashionUnited's roundup, so there's already a shared link | L31: Recommendation swap | M31: Substack DM | N31: https://substack.com | O31: Route unverified, check before sending | P31: Small audience, quick easy yes
A32: BoF Podcast / The Debrief | B32: Podcast | E32: High | F32: To pitch | H32: =IF(G32="","",G32+7) | K32: Business analysis podcast, listed as accepting guests | L32: Segment on how to validate a trend with data | M32: podcast@businessoffashion.com for speaker ideas, per show notes (not confirmed on BoF's own site) | N32: https://www.businessoffashion.com | O32: Route unverified, check before sending
A33: The Glossy Podcast | B33: Podcast | E33: High | F33: To pitch | H33: =IF(G33="","",G33+7) | K33: Weekly, active through 2026, regularly has trend guests | L33: Is it a trend? The data says... | M33: No booking route found, use the Glossy masthead or LinkedIn | N33: https://www.glossy.co/about-us | O33: Route unverified, check before sending
A34: Beyond Fashion Business | B34: Podcast | E34: Medium | F34: To pitch | H34: =IF(G34="","",G34+7) | K34: Listed as accepting guests, booking-call link in episode notes | L34: How data feeds buying decisions | M34: Booking link in episode notes | N34: https://rephonic.com/podcasts/the-future-of-fashion-business | O34: Route unverified, check before sending
A35: Drapers Talks | B35: Podcast | E35: Medium | F35: To pitch | H35: =IF(G35="","",G35+7) | K35: UK trade podcast with 2026 episodes | L35: UK retail trend data | M35: No route, use the Drapers editorial contacts | N35: https://www.drapersonline.com | O35: Route unverified, check before sending
A36: Spanish fashion podcasts (The Fashion Korner, Está de Moda) | B36: Podcast | E36: Medium | F36: To pitch | H36: =IF(G36="","",G36+7) | K36: Spanish-language video podcasts, good for interviews in Spanish | L36: Spanish-language guest spot on trend data | M36: No route found, DM on Instagram | N36: https://podcast.feedspot.com/podcasts_moda_espana/ | O36: Route unverified, check before sending
A37: Articles of Interest (Avery Trufelman) | B37: Podcast | E37: Low | F37: To pitch | H37: =IF(G37="","",G37+7) | K37: Garment-history episodes, highly curated | L37: Search-data angle for a single-item episode | M37: No guest route, low odds | N37: https://articlesofinterest.substack.com | O37: Route unverified, check before sending
A38: #journorequest on X and Bluesky | B38: Expert-source platform | E38: High | F38: To pitch | H38: =IF(G38="","",G38+7) | K38: Free, mostly UK-based journalist requests, and journalists are moving to Bluesky | L38: Reply to fashion and retail requests | M38: Search the hashtag daily or set an alert | N38: https://bsky.app/search?q=%23journorequest
A39: HARO (Featured.com) | B39: Expert-source platform | E39: High | F39: To pitch | H39: =IF(G39="","",G39+7) | K39: Relaunched free for sources in 2025, journalists post requests daily | L39: Answer fashion and retail trend requests as a data expert | M39: Free sign-up as a source | N39: https://www.helpareporter.com
A40: Qwoted | B40: Expert-source platform | E40: Medium | F40: To pitch | H40: =IF(G40="","",G40+7) | K40: Active platform where reporters find vetted experts | L40: Expert profile as fashion trend data analyst | M40: Sign up, free tier for experts unclear | N40: https://www.qwoted.com | O40: Route unverified, check before sending
A41: Source of Sources | B41: Expert-source platform | E41: Low | F41: To pitch | H41: =IF(G41="","",G41+7) | K41: Free email digests of journalist requests | L41: Same as HARO | M41: Sign up for the digest | N41: https://www.sourceofsources.com | O41: Route unverified, check before sending | P41: Official page not confirmed
...

Sheet Partners & Speaking
A1: Partners & Speaking
A2: Data companies to partner or co-publish with, and stages to speak on
A4: Name | B4: Type | C4: Segment | D4: Market | E4: Priority | F4: Status | G4: Last contact | H4: Follow up by | I4: Contact | J4: Where contact is published | K4: Why it fits | L4: Pitch angle | M4: How to reach | N4: Source link | O4: Flags | P4: Notes
A5: Lyst (Lyst Index) | B5: Data partner | E5: High | F5: To pitch | H5: =IF(G5="","",G5+7) | I5: press@lyst.com, plus a Lyst data-request page | J5: https://www.lyst.com/about/press/ | K5: You went to their LFW breakfast, and their Q2 2026 Index named Massimo Dutti the biggest climber | L5: Cite or co-publish around the Index, request Lyst data for a Trend Autopsy | M5: No public route found, follow up with your contact from the breakfast or LinkedIn | N5: https://www.lyst.com/the-lyst-index/ | O5: Partial competitor: shopping aggregator; Route unverified, check before sending | P5: Owned by Zozo since 2025
A6: Pinterest | B6: Data partner | E6: High | F6: To pitch | H6: =IF(G6="","",G6+7) | I6: press@pinterest.com | J6: https://newsroom.pinterest.com/en-gb/contact/ | K6: You met the Pinterest UK fashion team at their LFW salon, and Pinterest data already feeds DFB | L6: Commentary on Pinterest Predicts, creator programmes, a Pinterest data edition of Stop Calling Everything a Trend | M6: press@pinterest.com (shown on the NL newsroom page), and your warm contact from the event | N6: https://newsroom.pinterest.com/nl/contact/ | P6: Warm lead, follow up with whoever you met at the event first
A7: Trendalytics | B7: Data partner | E7: High | F7: To pitch | H7: =IF(G7="","",G7+7) | I7: press@trendalytics.co, general hello@trendalytics.co | J7: https://trendalytics.co/news | K7: Already a core DFB source for the Monthly Signal Check | L7: Co-branded monthly data drop, or a creator or analyst data licence | M7: About page lists a VP Marketing and Communications for press, email not visible in what we could read | N7: https://trendalytics.co/about | O7: Route unverified, check before sending | P7: Owned by Verishop since 2024
A8: WGSN | B8: Data partner | E8: High | F8: To pitch | H8: =IF(G8="","",G8+7) | I8: press@wgsn.com | J8: https://www.wgsn.com/en/wgsn/newsroom | K8: The trend authority, and its new Catwalks AI Dashboard (September 2026) sits right next to your Runway Decode work | L8: Pitch your search-validation method as a does-the-runway-hold-up commentary, or ask for dashboard access | M8: press@wgsn.com, or the global fashion press contact named on the press page, plus a media inquiry form for speaking | N8: https://www.wgsn.com/en/press/ | P8: Their newsroom invites requests for expert commentary and data validation
A9: EDITED | B9: Data partner | E9: Medium | F9: To pitch | H9: =IF(G9="","",G9+7) | I9: press@edited.com | J9: https://edited.com/contact-us/ | K9: Retail pricing and assortment data adds a what-actually-landed-in-stores layer | L9: Runway trend versus what retailers actually stocked | M9: Press@edited.com, from its own press pages | N9: https://edited.com | O9: Check: Farfetch may be a client
A10: Heuritech | B10: Data partner | E10: Medium | F10: To pitch | H10: =IF(G10="","",G10+7) | I10: press@heuritech.com | J10: https://heuritech.com/press/ | K10: AI image-recognition trend forecasting, very close to your runway tagging | L10: Ask for data to validate a DFB trend, or co-author a piece | M10: press@heuritech.com, their newsroom says they provide market data and schedule interviews | N10: https://heuritech.com/press/ | O10: Check: may supply Farfetch competitors | P10: Now part of Luxurynsight Group
A11: Launchmetrics (MIV) | B11: Data partner | E11: Medium | F11: To pitch | H11: =IF(G11="","",G11+7) | I11: Katherine Knight, VP Brand and Communications (email printed in the release), general info@launchmetrics.com | J11: https://www.launchmetrics.com/newsroom/launchmetrics-10-years | K11: Its media impact value data is a ready-made press-resonance check for your In The Press callouts | L11: Pair MIV with DFB runway shares for a season | M11: No public route found, LinkedIn | N11: https://launchmetrics.com/media-impact-value-usage | O11: Route unverified, check before sending
A12: Spate | B12: Data partner | E12: Medium | F12: To pitch | H12: =IF(G12="","",G12+7) | K12: Search-led trend data, the closest match to your Google Trends method | L12: Data partnership, strongest on beauty | M12: Book-a-call link on the site only | N12: https://spate.nyc | O12: Route unverified, check before sending
A13: Tagwalk | B13: Data partner | E13: Medium | F13: To pitch | H13: =IF(G13="","",G13+7) | I13: info@tag-walk.com | J13: https://www.tag-walk.com/en/page/contact | K13: Runway keyword search engine, a natural source for runway tagging | L13: Data partnership or guest analysis | M13: support@tag-walk.com or the request-a-call form, no press address found | N13: https://www.tag-walk.com/en/brand-visibility
A14: ThredUp / Depop / Vinted resale data | B14: Data partner | E14: Low | F14: To pitch | H14: =IF(G14="","",G14+7) | K14: Resale data gives you a counter-trend angle | L14: What resale says about this season's trends | M14: ThredUp media@thredup.com (2025 release, may be dated), Depop newsroom, Vinted via LinkedIn | N14: https://news.depop.com | O14: Route unverified, check before sending
A15: BoF VOICES | B15: Events & speaking | E15: High | F15: To pitch | H15: =IF(G15="","",G15+7) | K15: The top-tier industry thinking forum (2026 edition 1 to 4 December) | L15: Speaker pitch for 2027 | M15: Speaking enquiries contact listed on the VOICES 2026 page | N15: https://pages.businessoffashion.com/voices-2026/ | P15: Invite-only, so a long game
A16: British Fashion Council / LFW | B16: Events & speaking | E16: High | F16: To pitch | H16: =IF(G16="","",G16+7) | K16: Creator or press accreditation for next season | L16: Apply for February 2027 accreditation | M16: Press and buyers portal | N16: https://londonfashionweek.co.uk/trade
A17: Retail Week events | B17: Events & speaking | E17: High | F17: To pitch | H17: =IF(G17="","",G17+7) | K17: Retail-data audience, LIVE x The Grocer on 18 March 2027 in London | L17: Panel on trend data versus buying reality | M17: Speaker contact listed on the events page | N17: https://www.retail-week.com/events
A18: The Modems | B18: Events & speaking | E18: High | F18: To pitch | H18: =IF(G18="","",G18+7) | K18: You were at their Taking Taste Offline salon with Pinterest | L18: Follow up with your contact from the event about future salons or panels | M18: Your contact from the event | O18: Route unverified, check before sending | P18: Couldn't find a public page, use the handle you know
A19: Data Science London Meetup | B19: Events & speaking | E19: Medium | F19: To pitch | H19: =IF(G19="","",G19+7) | K19: Community data talks in London | L19: Talk submission | M19: Sessionize CFP (2026 round closed 20 September) | N19: https://sessionize.com/data-science-london-meetup/
A20: Fashion Decoded (Mapp) | B20: Events & speaking | E20: Medium | F20: To pitch | H20: =IF(G20="","",G20+7) | K20: AI and data in fashion retail, Pinterest UK and Google were on stage in 2026 | L20: Speaker pitch for 2027 | M20: No speaker route found | N20: https://mapp.com/cmp/fashion-decoded-2026-replay-hub/ | O20: Route unverified, check before sending
A21: London College of Fashion, Fashion Business School | B21: Events & speaking | E21: Medium | F21: To pitch | H21: =IF(G21="","",G21+7) | K21: Students in buying, merchandising and analytics | L21: Guest talk at Industry Day | M21: No direct route, LinkedIn to the course leaders | N21: https://www.arts.ac.uk/colleges/london-college-of-fashion/stories/fashion-business-school-industry-day | O21: Route unverified, check before sending
A22: PyData London | B22: Events & speaking | E22: Medium | F22: To pitch | H22: =IF(G22="","",G22+7) | K22: A fashion-data talk would stand out at a data conference | L22: Talk on runway tagging plus search validation | M22: CFP, the 2026 one closed in February, watch for 2027 | N22: https://pretalx.com/pydata-london-2026/cfp
A23: Women in Data UK | B23: Events & speaking | E23: Medium | F23: To pitch | H23: =IF(G23="","",G23+7) | K23: Big network of women in data, fits your profile exactly | L23: Speaker or panel | M23: No 2026 speaker call found, LinkedIn | N23: https://womenindata.co.uk | O23: Route unverified, check before sending
H24: =IF(G24="","",G24+7)
H25: =IF(G25="","",G25+7)
H26: =IF(G26="","",G26+7)
H27: =IF(G27="","",G27+7)
H28: =IF(G28="","",G28+7)
H29: =IF(G29="","",G29+7)
H30: =IF(G30="","",G30+7)
H31: =IF(G31="","",G31+7)
H32: =IF(G32="","",G32+7)
H33: =IF(G33="","",G33+7)
H34: =IF(G34="","",G34+7)
H35: =IF(G35="","",G35+7)
... H63: =IF(G63="","",G63+7)

Sheet Events
A1: Events
A2: Awards, fashion weeks, conferences and creator events, October 2026 to end of 2027, sorted by date
A4: Month | B4: Starts | C4: Ends | D4: Event | E4: Type | F4: City | G4: Status | H4: Deadline | I4: Dates confirmed? | J4: When (if not confirmed) | K4: How to get in | L4: Contact | M4: Source link | N4: Notes
A5: Oct 2026 | B5: 46322 | D5: WWD Honors | E5: Awards | F5: New York | G5: Want to go | I5: Yes | K5: Invite only, approach the WWD and Fairchild Media events team | M5: https://www.webwire.com/ViewPressRel.asp?aId=358636 | N5: Bernard Arnault receives the John B. Fairchild Honor this year
A6: Nov 2026 | D6: Harper's Bazaar UK Women of the Year | E6: Awards | F6: London | G6: Want to go | I6: No | J6: Usually early November (6 Nov in 2025, at Claridge's), 2026 date not found | K6: Invite only, Hearst UK and Bazaar events or PR | M6: https://www.fipp.com/news/harpers-bazaars-women-of-the-year-awards-return-for-2025/
A7: Nov 2026 | D7: British GQ Men of the Year | E7: Awards | F7: London | G7: Want to go | I7: No | J7: Usually November (19 Nov in 2024), 2026 date not found | K7: Invite only, Condé Nast UK events or PR | M7: https://inpublishing.co.uk/articles/british-gq-men-of-the-year-returns-24744
A8: Nov 2026 | D8: Fashion Trust Arabia Awards | E8: Awards | F8: Doha | G8: Want to go | I8: No | J8: Usually November (22 Nov in 2025), 2026 date not found | K8: Invite only, approach the FTA press office | M8: https://fashionunited.uk/news/fashion/fashion-trust-arabia-names-2025-prize-winners-in-qatar/2025120185142
A9: Nov 2026 | B9: 46328 | D9: CFDA Fashion Awards | E9: Awards | F9: New York | G9: Want to go | I9: Yes | K9: Invite only or brand tables, approach CFDA comms or a sponsoring brand's PR | M9: https://cfda.com/news/save-the-date-the-cfda-fashion-awards-presented-by-amazon-fashion-are-set-for-nov-2/ | N9: At the American Museum of Natural History, hosted by Keke Palmer
A10: Nov 2026 | B10: 46335 | C10: 46338 | D10: Web Summit | E10: Data & tech | F10: Lisbon | G10: Want to go | I10: Yes | K10: Paid ticket, speaker applications through Web Summit | M10: https://english.rvo.nl/events/web-summit-2026-lisbon
A11: Nov 2026 | B11: 46337 | D11: Drapers Awards | E11: Awards | F11: London | G11: Want to go | I11: Yes | K11: Paid tables through Drapers (Emap) | M11: https://www.sussexexpress.co.uk/business/eastbourne-based-business-shortlisted-for-fashion-industry-leading-award-9253997 | N11: At Old Billingsgate, date from a single source
A12: Nov 2026 | B12: 46356 | D12: The Fashion Awards (British Fashion Council) | E12: Awards | F12: London | G12: Want to go | I12: Yes | K12: Invite or BFC tables, ask the BFC press office about media accreditation | M12: https://fashionunited.uk/news/fashion/bfc-announces-fashion-awards-2026-nominees/2026091690370 | N12: At the Royal Albert Hall. Public tickets for 2026 not confirmed
A13: Dec 2026 | D13: Copenhagen Fashion Week AW27 accreditation opens | E13: Fashion week | F13: Copenhagen | G13: Want to go | I13: No | J13: Probably early December (last season it ran 4 Dec to 23 Jan) | K13: Apply through the CPHFW accreditation system | M13: https://copenhagenfashionweek.com/application/show-presentation-schedule-information
A14: Dec 2026 | D14: London Fashion Week AW27 accreditation opens | E14: Fashion week | F14: London | G14: Want to go | I14: No | J14: Probably December to January, alongside the provisional schedule | K14: BFC accreditation: Instagram 35k+, TikTok 100k+ or a blog or newsletter with 15,000+ monthly unique visitors, plus proof of work from the past 12 months | M14: https://londonfashionweek.co.uk/accreditation-criteria | N14: Creator accreditation covers the NEWGEN Show Space only, individual show seats come from each brand's PR
A15: Dec 2026 | B15: 46357 | C15: 46360 | D15: BoF VOICES | E15: Conference | F15: Oxfordshire | G15: Want to go | I15: Yes | K15: Invite only, but there's an invitation-request form open now and BoF says it replies within 14 days | M15: https://pages.businessoffashion.com/voices-2026/ | N15: At Soho Farmhouse. Request an invite this week
A16: Jan 2027 | B16: 46397 | C16: 46399 | D16: NRF Retail's Big Show | E16: Conference | F16: New York | G16: Want to go | I16: Yes | K16: Paid ticket, speaker proposals through NRF | M16: https://retailboss.co/events/nrf-2027-retails-big-show/
A17: Jan 2027 | B17: 46402 | C17: 46406 | D17: Milan Men's Fashion Week FW27 | E17: Fashion week | F17: Milan | G17: Want to go | I17: Yes | K17: CNMI accreditation | M17: https://thesybarite.co/experiences/milan-fashion-week-autumn-winter-2027 | N17: Single source
A18: Jan 2027 | B18: 46406 | C18: 46411 | D18: Paris Men's Fashion Week FW27 | E18: Fashion week | F18: Paris | G18: Want to go | I18: Yes | K18: FHCM press accreditation, show invites through each brand's PR | M18: https://www.fhcm.paris/en/next-dates
A19: Jan 2027 | B19: 46412 | C19: 46415 | D19: Paris Haute Couture SS27 | E19: Fashion week | F19: Paris | G19: Want to go | I19: Yes | K19: FHCM accreditation plus house PR invites | M19: https://www.fhcm.paris/en/next-dates
A20: Feb 2027 | D20: New York Fashion Week AW27 | E20: Fashion week | F20: New York | G20: Want to go | I20: No | J20: February 2027, exact dates conflict between sources (2026 was 11 to 16 Feb) | K20: Register through the CFDA's media registration when the schedule drops (mid January), then email each show's PR from the CFDA Fashion Calendar with your stats | M20: https://cfda.com/news/nyfw-mens-media-retail-registration-is-open/ | N20: Avoid paid third-party NYFW passes. Perfect timing for a Ground Data New York street check
A21: Feb 2027 | D21: London Fashion Week AW27 | E21: Fashion week | F21: London | G21: Want to go | I21: No | J21: February 2027, exact dates conflict between sources (2026 was 19 to 23 Feb) | K21: BFC accreditation, then pitch brand PRs for show seats | M21: https://www.britishfashioncouncil.co.uk
A22: Feb 2027 | B22: 46419 | C22: 46423 | D22: Copenhagen Fashion Week AW27 | E22: Fashion week | F22: Copenhagen | G22: Want to go | I22: Yes | K22: Accreditation is open to creators, and Substack has run creator sessions here before | M22: https://copenhagenfashionweek.com/ | N22: Most creator-friendly accreditation of the big weeks
A23: Feb 2027 | B23: 46441 | C23: 46447 | D23: Milan Fashion Week Women's AW27 | E23: Fashion week | F23: Milan | G23: Want to go | I23: Yes | K23: CNMI accreditation | M23: https://www.milanofinanza.it/news/milano-un-febbraio-2027-caldo-tra-moda-e-motori-2716565
A24: Feb 2027 | B24: 46443 | D24: Retail Week Awards | E24: Awards | F24: London | G24: Want to go | I24: Yes | K24: Paid tables | M24: https://www.retail-week.com/events | N24: At Grosvenor House
A25: Mar 2027 | D25: LVMH Prize semi-final | E25: Awards | F25: Paris | G25: Want to go | I25: No | J25: Usually early March (4 to 5 Mar in 2026) | K25: Invite only for press and buyers, LVMH Prize press office | M25: https://www.lvmh.com/en/news-lvmh/2026-lvmh-prize-for-young-fashion-designers13th-edition
A26: Mar 2027 | D26: Drapers Conscious Fashion Summit | E26: Conference | F26: London | G26: Want to go | I26: No | J26: Usually March (11 Mar in 2026) | K26: Paid ticket, pitch Drapers events for a speaking slot | M26: https://www.fibre2fashion.com/trade-fairs/drapers-conscious-fashion-summit-2026-65414
A27: Mar 2027 | B27: 46447 | C27: 46455 | D27: Paris Fashion Week Women's AW27 | E27: Fashion week | F27: Paris | G27: Want to go | I27: Yes | K27: FHCM accreditation plus brand PR | M27: https://www.fhcm.paris/en/next-dates | N27: FashionUnited lists 28 Feb to 8 Mar, check the FHCM calendar
A28: Mar 2027 | B28: 46464 | D28: LIVE: Retail Week x The Grocer | E28: Conference | F28: London | G28: Want to go | I28: Yes | K28: Paid ticket, speaker contact on the Retail Week events page | M28: https://live.retail-week.com/
A29: Mar 2027 | B29: 46468 | C29: 46470 | D29: Shoptalk Spring | E29: Conference | F29: Las Vegas | G29: Want to go | I29: Yes | K29: Paid, with a speaker and media programme | M29: https://www.beri.net/events/shoptalk-spring-2027
A30: Apr 2027 | D30: MAPP Fashion Decoded | E30: Conference | F30: London | G30: Want to go | I30: No | J30: Usually April (16 Apr in 2026) | K30: Ticket through MAPP | M30: https://machalliance.org/events/mapp-fashion-decoded-2026
A31: May 2027 | D31: Vogue Business Global Summit | E31: Conference | F31: France | G31: Want to go | I31: No | J31: Usually May (11 to 12 May in 2026) | K31: Invite or paid | M31: https://zapiet.com/events/vogue-business-summit-2026
A32: May 2027 | D32: Global Fashion Summit | E32: Conference | F32: Copenhagen | G32: Want to go | I32: No | J32: Possibly 25 to 27 May 2027, sources conflict | K32: Paid or by application | M32: https://www.worldfootwear.com/events/global-fashion-summit-copenhagen-denmark-/5822.html
A33: May 2027 | B33: 46510 | D33: Met Gala | E33: Awards | F33: New York | G33: Want to go | I33: Yes | K33: Invite only and not realistic to request, cover it as content instead | M33: https://vogue.ph/fashion/everything-you-need-to-know-met-gala-2027/ | N33: Reported theme John Galliano: Horizons, and the date may move
A34: Jun 2027 | D34: PyData London | E34: Data & tech | F34: London | G34: Want to go | I34: No | J34: Usually early June, CFP deadline usually mid February (16 Feb in 2026) | K34: Speaker CFP (speakers get a free ticket) or paid ticket | M34: https://pretalx.com/pydata-london-2026/cfp | N34: Submit a talk on runway tagging plus search validation by mid February
A35: Jun 2027 | B35: 46539 | C35: 46541 | D35: Shoptalk Europe | E35: Conference | F35: Barcelona | G35: Want to go | I35: Yes | K35: Paid, with a speaker and media programme | M35: https://www.cantonfair.net/event/31439-shoptalk-europe-2027-europes-home-for-retail-innovation-1-3-june-barcelona
A36: Jun 2027 | B36: 46559 | C36: 46563 | D36: Cannes Lions (LIONS Creators) | E36: Creator | F36: Cannes | G36: Want to go | I36: Yes | K36: Paid pass, LIONS Creators programme | M36: https://en.cannes-france.com/offers/cannes-lions-international-festival-of-creativity-cannes-en-3657190/
A37: Jul 2027 | B37: 46573 | C37: 46576 | D37: Paris Haute Couture FW27 | E37: Fashion week | F37: Paris | G37: Want to go | I37: Yes | K37: FHCM plus house PR | M37: https://www.fhcm.paris/en/next-dates
A38: Aug 2027 | D38: LTK Con | E38: Creator | F38: Dallas | G38: Want to go | I38: No | J38: Usually late August (25 to 27 Aug in 2026) | K38: Invite only for LTK creators | M38: https://retailboss.co/?p=19549
A39: Sep 2027 | D39: New York Fashion Week SS28 | E39: Fashion week | F39: New York | G39: Want to go | I39: No | J39: Usually September (10 to 15 Sept in 2026) | K39: CFDA registration | M39: https://fashionunited.uk/news/fashion/cfda-unveils-nyfw-schedule-with-new-additions-returning-brands-and-fur-free-debut/2026070188958
A40: Sep 2027 | D40: ELLE Style Awards UK | E40: Awards | F40: London | G40: Want to go | I40: No | J40: Usually early September, opening LFW | K40: Invite only, Hearst UK ELLE PR | M40: https://www.hearstmagazinesinternational.com/news/elle-uk-celebrates-the-2025-elle-style-awards/
A41: Sep 2027 | D41: London Fashion Week SS28 | E41: Fashion week | F41: London | G41: Want to go | I41: No | J41: Usually mid September (17 to 21 Sept in 2026) | K41: BFC accreditation | M41: https://fashionunited.uk/news/fashion/lfw-ss27-bfc-announces-provisional-schedule/2026072089310
...
